5:return {{["x"] = 0, ["param2"] = 2, ["y"] = 0, ["param1"] = 61, ["z"] = 1, ["name"] = "mex_moreblocks:vine"}, {["x"] = 0, ["param2"] = 2, ["y"] = 0, ["param1"] = 77, ["z"] = 2, ["name"] = "mex_moreblocks:vine"}, {["x"] = 0, ["param2"] = 2, ["y"] = 0, ["param1"] = 93, ["z"] = 3, ["name"] = "mex_moreblocks:vine"}, {["x"] = 0, ["param2"] = 2, ["y"] = 0, ["param1"] = 109, ["z"] = 4, ["name"] = "mex_moreblocks:vine"}, {["x"] = 0, ["param2"] = 2, ["y"] = 0, ["param1"] = 125, ["z"] = 5, ["name"] = "mex_moreblocks:vine"}, {["x"] = 0, ["param2"] = 2, ["y"] = 0, ["param1"] = 109, ["z"] = 6, ["name"] = "mex_moreblocks:vine"}, {["x"] = 0, ["param2"] = 2, ["y"] = 1, ["param1"] = 93, ["z"] = 2, ["name"] = "mex_moreblocks:vine"}, {["x"] = 0, ["param2"] = 2, ["y"] = 1, ["param1"] = 109, ["z"] = 3, ["name"] = "mex_moreblocks:vine"}, {["x"] = 0, ["param2"] = 2, ["y"] = 2, ["param1"] = 109, ["z"] = 2, ["name"] = "mex_moreblocks:vine"}, {["x"] = 1, ["param2"] = 4, ["y"] = 0, ["param1"] = 46, ["z"] = 0, ["name"] = "mex_moreblocks:vine"}, {["x"] = 1, ["y"] = 0, ["z"] = 1, ["name"] = "mex_moreblocks:basalt_brick"}, {["x"] = 1, ["y"] = 0, ["z"] = 2, ["name"] = "mex_moreblocks:basalt_brick"}, {["x"] = 1, ["y"] = 0, ["z"] = 3, ["name"] = "mex_moreblocks:basalt_brick"}, {["x"] = 1, ["y"] = 0, ["z"] = 4, ["name"] = "mex_moreblocks:basalt_brick"}, {["x"] = 1, ["y"] = 0, ["z"] = 5, ["name"] = "mex_moreblocks:basalt_brick"}, {["x"] = 1, ["y"] = 0, ["z"] = 6, ["name"] = "mex_moreblocks:basalt_brick"}, {["x"] = 1, ["y"] = 0, ["z"] = 7, ["name"] = "mex_moreblocks:basalt_brick"}, {["x"] = 1, ["param2"] = 5, ["y"] = 0, ["param1"] = 62, ["z"] = 8, ["name"] = "mex_moreblocks:vine"}, {["x"] = 1, ["y"] = 1, ["z"] = 1, ["name"] = "mex_moreblocks:basalt_brick"}, {["x"] = 1, ["y"] = 1, ["z"] = 2, ["name"] = "mex_moreblocks:basalt_brick"}, {["x"] = 1, ["y"] = 1, ["z"] = 3, ["name"] = "mex_moreblocks:basalt_brick"}, {["x"] = 1, ["y"] = 1, ["z"] = 4, ["name"] = "mex_moreblocks:basalt_brick"}, {["x"] = 1, ["y"] = 1, ["z"] = 5, ["name"] = "mex_moreblocks:basalt_brick"}, {["x"] = 1, ["y"] = 1, ["z"] = 6, ["name"] = "mex_moreblocks:basalt_brick"}, {["x"] = 1, ["y"] = 1, ["z"] = 7, ["name"] = "mex_moreblocks:basalt_brick"}, {["x"] = 1, ["y"] = 2, ["z"] = 1, ["name"] = "mex_moreblocks:basalt_brick"}, {["x"] = 1, ["y"] = 2, ["z"] = 2, ["name"] = "mex_moreblocks:basalt_brick"}, {["x"] = 1, ["param2"] = 1, ["y"] = 2, ["param1"] = 157, ["z"] = 4, ["name"] = "xpanes:obsidian_pane_flat"}, {["x"] = 1, ["param2"] = 3, ["y"] = 2, ["param1"] = 172, ["z"] = 5, ["name"] = "xpanes:obsidian_pane_flat"}, {["x"] = 1, ["y"] = 2, ["z"] = 6, ["name"] = "mex_moreblocks:basalt_brick"}, {["x"] = 1, ["y"] = 2, ["z"] = 7, ["name"] = "mex_moreblocks:basalt_brick"}, {["x"] = 1, ["y"] = 3, ["z"] = 2, ["name"] = "mex_moreblocks:basalt_brick"}, {["x"] = 1, ["y"] = 3, ["z"] = 3, ["name"] = "mex_moreblocks:basalt_brick"}, {["x"] = 1, ["y"] = 3, ["z"] = 4, ["name"] = "mex_moreblocks:basalt_brick"}, {["x"] = 1, ["y"] = 3, ["z"] = 5, ["name"] = "mex_moreblocks:basalt_brick"}, {["x"] = 1, ["y"] = 3, ["z"] = 6, ["name"] = "mex_moreblocks:basalt_brick"}, {["x"] = 1, ["y"] = 3, ["z"] = 7, ["name"] = "mex_moreblocks:basalt_brick"}, {["x"] = 1, ["y"] = 4, ["z"] = 2, ["name"] = "mex_moreblocks:basalt_brick"}, {["x"] = 1, ["y"] = 4, ["z"] = 3, ["name"] = "mex_moreblocks:basalt_brick"}, {["x"] = 1, ["y"] = 4, ["z"] = 4, ["name"] = "mex_moreblocks:basalt_brick"}, {["x"] = 1, ["y"] = 4, ["z"] = 5, ["name"] = "mex_moreblocks:basalt_brick"}, {["x"] = 1, ["y"] = 4, ["z"] = 6, ["name"] = "mex_moreblocks:basalt_brick"}, {["x"] = 1, ["param2"] = 1, ["y"] = 5, ["param1"] = 46, ["z"] = 2, ["name"] = "stairs:stair_basalt_brick"}, {["x"] = 1, ["param2"] = 1, ["y"] = 5, ["param1"] = 61, ["z"] = 3, ["name"] = "stairs:stair_basalt_brick"}, {["x"] = 1, ["param2"] = 1, ["y"] = 5, ["param1"] = 77, ["z"] = 4, ["name"] = "stairs:stair_basalt_brick"}, {["x"] = 1, ["param2"] = 1, ["y"] = 5, ["param1"] = 94, ["z"] = 5, ["name"] = "stairs:stair_basalt_brick"}, {["x"] = 1, ["param2"] = 1, ["y"] = 5, ["param1"] = 78, ["z"] = 6, ["name"] = "stairs:stair_basalt_brick"}, {["x"] = 2, ["y"] = 0, ["z"] = 1, ["name"] = "mex_moreblocks:basalt_brick"}, {["x"] = 2, ["y"] = 0, ["z"] = 2, ["name"] = "mex_moreblocks:marble_tile"}, {["x"] = 2, ["y"] = 0, ["z"] = 3, ["name"] = "mex_moreblocks:marble_tile"}, {["x"] = 2, ["y"] = 0, ["z"] = 4, ["name"] = "mex_moreblocks:marble_tile"}, {["x"] = 2, ["y"] = 0, ["z"] = 5, ["name"] = "mex_moreblocks:marble_tile"}, {["x"] = 2, ["y"] = 0, ["z"] = 6, ["name"] = "mex_moreblocks:marble_tile"}, {["x"] = 2, ["y"] = 0, ["z"] = 7, ["name"] = "mex_moreblocks:basalt_brick"}, {["x"] = 2, ["param2"] = 5, ["y"] = 0, ["param1"] = 46, ["z"] = 8, ["name"] = "mex_moreblocks:vine"}, {["x"] = 2, ["y"] = 1, ["z"] = 1, ["name"] = "mex_moreblocks:basalt_brick"}, {["x"] = 2, ["y"] = 1, ["param1"] = 187, ["z"] = 6, ["name"] = "ts_furniture:default_junglewood_table"}, {["x"] = 2, ["y"] = 1, ["z"] = 7, ["name"] = "mex_moreblocks:basalt_brick"}, {["x"] = 2, ["y"] = 2, ["z"] = 1, ["name"] = "mex_moreblocks:basalt_brick"}, {["x"] = 2, ["param2"] = 3, ["y"] = 2, ["param1"] = 204, ["z"] = 6, ["name"] = "mex_moreblocks:candle"}, {["x"] = 2, ["y"] = 2, ["z"] = 7, ["name"] = "mex_moreblocks:basalt_brick"}, {["x"] = 2, ["y"] = 3, ["z"] = 1, ["name"] = "mex_moreblocks:basalt_brick"}, {["x"] = 2, ["y"] = 3, ["z"] = 7, ["name"] = "mex_moreblocks:basalt_brick"}, {["x"] = 2, ["y"] = 4, ["z"] = 1, ["name"] = "mex_moreblocks:basalt_brick"}, {["x"] = 2, ["y"] = 4, ["z"] = 2, ["name"] = "default:pine_wood"}, {["x"] = 2, ["y"] = 4, ["z"] = 3, ["name"] = "default:pine_wood"}, {["x"] = 2, ["y"] = 4, ["z"] = 4, ["name"] = "default:pine_wood"}, {["x"] = 2, ["y"] = 4, ["z"] = 5, ["name"] = "default:pine_wood"}, {["x"] = 2, ["y"] = 4, ["z"] = 6, ["name"] = "default:pine_wood"}, {["x"] = 2, ["y"] = 4, ["z"] = 7, ["name"] = "mex_moreblocks:basalt_brick"}, {["x"] = 2, ["y"] = 5, ["param1"] = 14, ["z"] = 1, ["name"] = "stairs:stair_basalt_brick"}, {["x"] = 2, ["y"] = 5, ["z"] = 2, ["name"] = "mex_moreblocks:basalt_brick"}, {["x"] = 2, ["y"] = 5, ["z"] = 3, ["name"] = "mex_moreblocks:basalt_brick"}, {["x"] = 2, ["y"] = 5, ["z"] = 4, ["name"] = "mex_moreblocks:basalt_brick"}, {["x"] = 2, ["y"] = 5, ["z"] = 5, ["name"] = "mex_moreblocks:basalt_brick"}, {["x"] = 2, ["y"] = 5, ["z"] = 6, ["name"] = "mex_moreblocks:basalt_brick"}, {["x"] = 2, ["param2"] = 2, ["y"] = 5, ["param1"] = 46, ["z"] = 7, ["name"] = "stairs:stair_basalt_brick"}, {["x"] = 2, ["param2"] = 1, ["y"] = 6, ["param1"] = 14, ["z"] = 2, ["name"] = "stairs:stair_outer_basalt_brick"}, {["x"] = 2, ["param2"] = 1, ["y"] = 6, ["param1"] = 29, ["z"] = 3, ["name"] = "stairs:stair_basalt_brick"}, {["x"] = 2, ["param2"] = 1, ["y"] = 6, ["param1"] = 45, ["z"] = 4, ["name"] = "stairs:stair_basalt_brick"}, {["x"] = 2, ["param2"] = 1, ["y"] = 6, ["param1"] = 62, ["z"] = 5, ["name"] = "stairs:stair_basalt_brick"}, {["x"] = 2, ["param2"] = 2, ["y"] = 6, ["param1"] = 46, ["z"] = 6, ["name"] = "stairs:stair_outer_basalt_brick"}, {["x"] = 3, ["y"] = 0, ["z"] = 1, ["name"] = "mex_moreblocks:basalt_brick"}, {["x"] = 3, ["y"] = 0, ["z"] = 2, ["name"] = "mex_moreblocks:marble_tile"}, {["x"] = 3, ["y"] = 0, ["z"] = 3, ["name"] = "mex_moreblocks:marble_tile"}, {["x"] = 3, ["y"] = 0, ["z"] = 4, ["name"] = "mex_moreblocks:marble_tile"}, {["x"] = 3, ["y"] = 0, ["z"] = 5, ["name"] = "mex_moreblocks:marble_tile"}, {["x"] = 3, ["y"] = 0, ["z"] = 6, ["name"] = "mex_moreblocks:marble_tile"}, {["x"] = 3, ["y"] = 0, ["z"] = 7, ["name"] = "mex_moreblocks:basalt_brick"}, {["x"] = 3, ["param2"] = 5, ["y"] = 0, ["param1"] = 30, ["z"] = 8, ["name"] = "mex_moreblocks:vine"}, {["x"] = 3, ["y"] = 1, ["z"] = 1, ["name"] = "mex_moreblocks:basalt_brick"}, {["x"] = 3, ["y"] = 1, ["param1"] = 170, ["z"] = 6, ["name"] = "ts_furniture:default_junglewood_chair"}, {["x"] = 3, ["y"] = 1, ["z"] = 7, ["name"] = "mex_moreblocks:basalt_brick"}, {["x"] = 3, ["y"] = 2, ["z"] = 1, ["name"] = "mex_moreblocks:basalt_brick"}, {["x"] = 3, ["y"] = 2, ["z"] = 7, ["name"] = "mex_moreblocks:basalt_brick"}, {["x"] = 3, ["y"] = 3, ["z"] = 1, ["name"] = "mex_moreblocks:basalt_brick"}, {["x"] = 3, ["y"] = 3, ["z"] = 7, ["name"] = "mex_moreblocks:basalt_brick"}, {["x"] = 3, ["y"] = 4, ["z"] = 1, ["name"] = "mex_moreblocks:basalt_brick"}, {["x"] = 3, ["y"] = 4, ["z"] = 2, ["name"] = "default:pine_wood"}, {["x"] = 3, ["y"] = 4, ["z"] = 3, ["name"] = "default:pine_wood"}, {["x"] = 3, ["y"] = 4, ["z"] = 4, ["name"] = "default:pine_wood"}, {["x"] = 3, ["y"] = 4, ["z"] = 5, ["name"] = "default:pine_wood"}, {["x"] = 3, ["y"] = 4, ["z"] = 6, ["name"] = "default:pine_wood"}, {["x"] = 3, ["y"] = 4, ["z"] = 7, ["name"] = "mex_moreblocks:basalt_brick"}, {["x"] = 3, ["y"] = 5, ["z"] = 2, ["name"] = "mex_moreblocks:basalt_brick"}, {["x"] = 3, ["y"] = 5, ["z"] = 3, ["name"] = "mex_moreblocks:basalt_brick"}, {["x"] = 3, ["y"] = 5, ["z"] = 4, ["name"] = "mex_moreblocks:basalt_brick"}, {["x"] = 3, ["y"] = 5, ["z"] = 5, ["name"] = "mex_moreblocks:basalt_brick"}, {["x"] = 3, ["y"] = 5, ["z"] = 6, ["name"] = "mex_moreblocks:basalt_brick"}, {["x"] = 3, ["param2"] = 2, ["y"] = 5, ["param1"] = 30, ["z"] = 7, ["name"] = "stairs:stair_basalt_brick"}, {["x"] = 3, ["y"] = 6, ["param1"] = 14, ["z"] = 2, ["name"] = "stairs:stair_basalt_brick"}, {["x"] = 3, ["y"] = 6, ["z"] = 3, ["name"] = "mex_moreblocks:basalt_brick"}, {["x"] = 3, ["y"] = 6, ["z"] = 4, ["name"] = "mex_moreblocks:basalt_brick"}, {["x"] = 3, ["y"] = 6, ["z"] = 5, ["name"] = "mex_moreblocks:basalt_brick"}, {["x"] = 3, ["param2"] = 2, ["y"] = 6, ["param1"] = 30, ["z"] = 6, ["name"] = "stairs:stair_basalt_brick"}, {["x"] = 3, ["param2"] = 1, ["y"] = 7, ["param1"] = 14, ["z"] = 3, ["name"] = "stairs:stair_outer_basalt_brick"}, {["x"] = 3, ["param2"] = 1, ["y"] = 7, ["param1"] = 13, ["z"] = 4, ["name"] = "stairs:stair_basalt_brick"}, {["x"] = 3, ["param2"] = 2, ["y"] = 7, ["param1"] = 30, ["z"] = 5, ["name"] = "stairs:stair_outer_basalt_brick"}, {["x"] = 4, ["y"] = 0, ["z"] = 1, ["name"] = "mex_moreblocks:basalt_brick"}, {["x"] = 4, ["y"] = 0, ["z"] = 2, ["name"] = "mex_moreblocks:marble_tile"}, {["x"] = 4, ["y"] = 0, ["z"] = 3, ["name"] = "mex_moreblocks:marble_tile"}, {["x"] = 4, ["y"] = 0, ["z"] = 4, ["name"] = "mex_moreblocks:marble_tile"}, {["x"] = 4, ["y"] = 0, ["z"] = 5, ["name"] = "mex_moreblocks:marble_tile"}, {["x"] = 4, ["y"] = 0, ["z"] = 6, ["name"] = "mex_moreblocks:marble_tile"}, {["x"] = 4, ["y"] = 0, ["z"] = 7, ["name"] = "mex_moreblocks:basalt_brick"}, {["x"] = 4, ["param2"] = 5, ["y"] = 0, ["param1"] = 14, ["z"] = 8, ["name"] = "mex_moreblocks:vine"}, {["x"] = 4, ["y"] = 1, ["z"] = 1, ["name"] = "mex_moreblocks:basalt_brick"}, {["x"] = 4, ["y"] = 1, ["z"] = 7, ["name"] = "mex_moreblocks:basalt_brick"}, {["x"] = 4, ["param2"] = 5, ["y"] = 1, ["param1"] = 30, ["z"] = 8, ["name"] = "mex_moreblocks:vine"}, {["x"] = 4, ["y"] = 2, ["z"] = 1, ["name"] = "mex_moreblocks:basalt_brick"}, {["x"] = 4, ["y"] = 2, ["z"] = 7, ["name"] = "mex_moreblocks:basalt_brick"}, {["x"] = 4, ["y"] = 3, ["z"] = 1, ["name"] = "mex_moreblocks:basalt_brick"}, {["x"] = 4, ["y"] = 3, ["z"] = 7, ["name"] = "mex_moreblocks:basalt_brick"}, {["x"] = 4, ["y"] = 4, ["z"] = 1, ["name"] = "mex_moreblocks:basalt_brick"}, {["x"] = 4, ["y"] = 4, ["z"] = 2, ["name"] = "default:pine_wood"}, {["x"] = 4, ["y"] = 4, ["z"] = 3, ["name"] = "default:pine_wood"}, {["x"] = 4, ["y"] = 4, ["z"] = 4, ["name"] = "default:pine_wood"}, {["x"] = 4, ["y"] = 4, ["z"] = 5, ["name"] = "default:pine_wood"}, {["x"] = 4, ["y"] = 4, ["z"] = 6, ["name"] = "default:pine_wood"}, {["x"] = 4, ["y"] = 4, ["z"] = 7, ["name"] = "mex_moreblocks:basalt_brick"}, {["x"] = 4, ["y"] = 5, ["param1"] = 14, ["z"] = 1, ["name"] = "stairs:stair_basalt_brick"}, {["x"] = 4, ["y"] = 5, ["z"] = 2, ["name"] = "mex_moreblocks:basalt_brick"}, {["x"] = 4, ["y"] = 5, ["z"] = 3, ["name"] = "mex_moreblocks:basalt_brick"}, {["x"] = 4, ["y"] = 5, ["z"] = 4, ["name"] = "default:goldblock"}, {["x"] = 4, ["y"] = 5, ["z"] = 5, ["name"] = "mex_moreblocks:basalt_brick"}, {["x"] = 4, ["y"] = 5, ["z"] = 6, ["name"] = "mex_moreblocks:basalt_brick"}, {["x"] = 4, ["param2"] = 2, ["y"] = 5, ["param1"] = 14, ["z"] = 7, ["name"] = "stairs:stair_basalt_brick"}, {["x"] = 4, ["y"] = 6, ["param1"] = 14, ["z"] = 2, ["name"] = "stairs:stair_basalt_brick"}, {["x"] = 4, ["y"] = 6, ["z"] = 3, ["name"] = "mex_moreblocks:basalt_brick"}, {["x"] = 4, ["y"] = 6, ["z"] = 5, ["name"] = "mex_moreblocks:basalt_brick"}, {["x"] = 4, ["param2"] = 2, ["y"] = 6, ["param1"] = 14, ["z"] = 6, ["name"] = "stairs:stair_basalt_brick"}, {["x"] = 4, ["y"] = 7, ["param1"] = 14, ["z"] = 3, ["name"] = "stairs:stair_basalt_brick"}, {["x"] = 4, ["y"] = 7, ["z"] = 4, ["name"] = "mex_moreblocks:basalt_brick"}, {["x"] = 4, ["param2"] = 2, ["y"] = 7, ["param1"] = 14, ["z"] = 5, ["name"] = "stairs:stair_basalt_brick"}, {["x"] = 4, ["param2"] = 2, ["y"] = 8, ["param1"] = 14, ["z"] = 4, ["name"] = "stairs:slab_basalt_brick"}, {["x"] = 5, ["y"] = 0, ["param1"] = 30, ["z"] = 0, ["name"] = "stairs:stair_basalt_brick"}, {["x"] = 5, ["y"] = 0, ["z"] = 1, ["name"] = "mex_moreblocks:marble_tile"}, {["x"] = 5, ["y"] = 0, ["z"] = 2, ["name"] = "mex_moreblocks:marble_tile"}, {["x"] = 5, ["y"] = 0, ["z"] = 3, ["name"] = "mex_moreblocks:marble_tile"}, {["x"] = 5, ["y"] = 0, ["z"] = 4, ["name"] = "mex_moreblocks:marble_tile"}, {["x"] = 5, ["y"] = 0, ["z"] = 5, ["name"] = "mex_moreblocks:marble_tile"}, {["x"] = 5, ["y"] = 0, ["z"] = 6, ["name"] = "mex_moreblocks:marble_tile"}, {["x"] = 5, ["y"] = 0, ["z"] = 7, ["name"] = "mex_moreblocks:basalt_brick"}, {["x"] = 5, ["param2"] = 5, ["y"] = 0, ["param1"] = 14, ["z"] = 8, ["name"] = "mex_moreblocks:vine"}, {["x"] = 5, ["meta"] = {["fields"] = {["state"] = "1"}, ["inventory"] = {}}, ["param2"] = 1, ["y"] = 1, ["param1"] = 62, ["z"] = 1, ["name"] = "doors:door_jungle_2_c"}, {["x"] = 5, ["y"] = 1, ["z"] = 7, ["name"] = "mex_moreblocks:basalt_brick"}, {["x"] = 5, ["param2"] = 5, ["y"] = 1, ["param1"] = 14, ["z"] = 8, ["name"] = "mex_moreblocks:vine"}, {["x"] = 5, ["y"] = 2, ["param1"] = 78, ["z"] = 1, ["name"] = "doors:hidden"}, {["x"] = 5, ["y"] = 2, ["z"] = 7, ["name"] = "mex_moreblocks:basalt_brick"}, {["x"] = 5, ["param2"] = 5, ["y"] = 2, ["param1"] = 30, ["z"] = 8, ["name"] = "mex_moreblocks:vine"}, {["x"] = 5, ["y"] = 3, ["z"] = 1, ["name"] = "mex_moreblocks:basalt_brick"}, {["x"] = 5, ["y"] = 3, ["z"] = 7, ["name"] = "mex_moreblocks:basalt_brick"}, {["x"] = 5, ["y"] = 4, ["z"] = 1, ["name"] = "mex_moreblocks:basalt_brick"}, {["x"] = 5, ["y"] = 4, ["z"] = 2, ["name"] = "default:pine_wood"}, {["x"] = 5, ["y"] = 4, ["z"] = 3, ["name"] = "default:pine_wood"}, {["x"] = 5, ["y"] = 4, ["z"] = 4, ["name"] = "default:pine_wood"}, {["x"] = 5, ["y"] = 4, ["z"] = 5, ["name"] = "default:pine_wood"}, {["x"] = 5, ["y"] = 4, ["z"] = 6, ["name"] = "default:pine_wood"}, {["x"] = 5, ["y"] = 4, ["z"] = 7, ["name"] = "mex_moreblocks:basalt_brick"}, {["x"] = 5, ["y"] = 5, ["param1"] = 14, ["z"] = 1, ["name"] = "stairs:stair_basalt_brick"}, {["x"] = 5, ["y"] = 5, ["z"] = 2, ["name"] = "mex_moreblocks:basalt_brick"}, {["x"] = 5, ["y"] = 5, ["z"] = 3, ["name"] = "mex_moreblocks:basalt_brick"}, {["x"] = 5, ["y"] = 5, ["z"] = 5, ["name"] = "mex_moreblocks:basalt_brick"}, {["x"] = 5, ["y"] = 5, ["z"] = 6, ["name"] = "mex_moreblocks:basalt_brick"}, {["x"] = 5, ["param2"] = 2, ["y"] = 5, ["param1"] = 14, ["z"] = 7, ["name"] = "stairs:stair_basalt_brick"}, {["x"] = 5, ["y"] = 6, ["param1"] = 14, ["z"] = 2, ["name"] = "stairs:stair_basalt_brick"}, {["x"] = 5, ["y"] = 6, ["z"] = 3, ["name"] = "mex_moreblocks:basalt_brick"}, {["x"] = 5, ["y"] = 6, ["z"] = 5, ["name"] = "mex_moreblocks:basalt_brick"}, {["x"] = 5, ["param2"] = 2, ["y"] = 6, ["param1"] = 14, ["z"] = 6, ["name"] = "stairs:stair_basalt_brick"}, {["x"] = 5, ["y"] = 7, ["param1"] = 14, ["z"] = 3, ["name"] = "stairs:stair_basalt_brick"}, {["x"] = 5, ["y"] = 7, ["z"] = 4, ["name"] = "mex_moreblocks:basalt_brick"}, {["x"] = 5, ["param2"] = 2, ["y"] = 7, ["param1"] = 14, ["z"] = 5, ["name"] = "stairs:stair_basalt_brick"}, {["x"] = 5, ["param2"] = 2, ["y"] = 8, ["param1"] = 14, ["z"] = 4, ["name"] = "stairs:slab_basalt_brick"}, {["x"] = 6, ["y"] = 0, ["z"] = 1, ["name"] = "mex_moreblocks:basalt_brick"}, {["x"] = 6, ["y"] = 0, ["z"] = 2, ["name"] = "mex_moreblocks:marble_tile"}, {["x"] = 6, ["y"] = 0, ["z"] = 3, ["name"] = "mex_moreblocks:marble_tile"}, {["x"] = 6, ["y"] = 0, ["z"] = 4, ["name"] = "mex_moreblocks:marble_tile"}, {["x"] = 6, ["y"] = 0, ["z"] = 5, ["name"] = "mex_moreblocks:marble_tile"}, {["x"] = 6, ["y"] = 0, ["z"] = 6, ["name"] = "mex_moreblocks:marble_tile"}, {["x"] = 6, ["y"] = 0, ["z"] = 7, ["name"] = "mex_moreblocks:basalt_brick"}, {["x"] = 6, ["param2"] = 5, ["y"] = 0, ["param1"] = 14, ["z"] = 8, ["name"] = "mex_moreblocks:vine"}, {["x"] = 6, ["y"] = 1, ["z"] = 1, ["name"] = "mex_moreblocks:basalt_brick"}, {["x"] = 6, ["y"] = 1, ["z"] = 7, ["name"] = "mex_moreblocks:basalt_brick"}, {["x"] = 6, ["y"] = 2, ["z"] = 1, ["name"] = "mex_moreblocks:basalt_brick"}, {["x"] = 6, ["y"] = 2, ["z"] = 7, ["name"] = "mex_moreblocks:basalt_brick"}, {["x"] = 6, ["y"] = 3, ["z"] = 1, ["name"] = "mex_moreblocks:basalt_brick"}, {["x"] = 6, ["y"] = 3, ["z"] = 7, ["name"] = "mex_moreblocks:basalt_brick"}, {["x"] = 6, ["param2"] = 5, ["y"] = 3, ["param1"] = 14, ["z"] = 8, ["name"] = "mex_moreblocks:vine"}, {["x"] = 6, ["y"] = 4, ["z"] = 1, ["name"] = "mex_moreblocks:basalt_brick"}, {["x"] = 6, ["y"] = 4, ["z"] = 2, ["name"] = "default:pine_wood"}, {["x"] = 6, ["y"] = 4, ["z"] = 3, ["name"] = "default:pine_wood"}, {["x"] = 6, ["y"] = 4, ["z"] = 4, ["name"] = "default:pine_wood"}, {["x"] = 6, ["y"] = 4, ["z"] = 5, ["name"] = "default:pine_wood"}, {["x"] = 6, ["y"] = 4, ["z"] = 6, ["name"] = "default:pine_wood"}, {["x"] = 6, ["y"] = 4, ["z"] = 7, ["name"] = "mex_moreblocks:basalt_brick"}, {["x"] = 6, ["y"] = 5, ["z"] = 2, ["name"] = "mex_moreblocks:basalt_brick"}, {["x"] = 6, ["y"] = 5, ["z"] = 3, ["name"] = "mex_moreblocks:basalt_brick"}, {["x"] = 6, ["y"] = 5, ["z"] = 5, ["name"] = "mex_moreblocks:basalt_brick"}, {["x"] = 6, ["y"] = 5, ["z"] = 6, ["name"] = "mex_moreblocks:basalt_brick"}, {["x"] = 6, ["param2"] = 2, ["y"] = 5, ["param1"] = 14, ["z"] = 7, ["name"] = "stairs:stair_basalt_brick"}, {["x"] = 6, ["y"] = 6, ["param1"] = 14, ["z"] = 2, ["name"] = "stairs:stair_basalt_brick"}, {["x"] = 6, ["y"] = 6, ["z"] = 3, ["name"] = "mex_moreblocks:basalt_brick"}, {["x"] = 6, ["y"] = 6, ["z"] = 5, ["name"] = "mex_moreblocks:basalt_brick"}, {["x"] = 6, ["param2"] = 2, ["y"] = 6, ["param1"] = 14, ["z"] = 6, ["name"] = "stairs:stair_basalt_brick"}, {["x"] = 6, ["y"] = 7, ["param1"] = 14, ["z"] = 3, ["name"] = "stairs:stair_basalt_brick"}, {["x"] = 6, ["y"] = 7, ["z"] = 4, ["name"] = "mex_moreblocks:basalt_brick"}, {["x"] = 6, ["param2"] = 2, ["y"] = 7, ["param1"] = 14, ["z"] = 5, ["name"] = "stairs:stair_basalt_brick"}, {["x"] = 6, ["param2"] = 2, ["y"] = 8, ["param1"] = 14, ["z"] = 4, ["name"] = "stairs:slab_basalt_brick"}, {["x"] = 7, ["param2"] = 4, ["y"] = 0, ["param1"] = 14, ["z"] = 0, ["name"] = "mex_moreblocks:vine"}, {["x"] = 7, ["y"] = 0, ["z"] = 1, ["name"] = "mex_moreblocks:basalt_brick"}, {["x"] = 7, ["y"] = 0, ["z"] = 2, ["name"] = "mex_moreblocks:basalt_brick"}, {["x"] = 7, ["y"] = 0, ["z"] = 3, ["name"] = "mex_moreblocks:marble_tile"}, {["x"] = 7, ["y"] = 0, ["z"] = 4, ["name"] = "mex_moreblocks:basalt_brick"}, {["x"] = 7, ["y"] = 0, ["z"] = 5, ["name"] = "mex_moreblocks:basalt_brick"}, {["x"] = 7, ["y"] = 0, ["z"] = 6, ["name"] = "mex_moreblocks:basalt_brick"}, {["x"] = 7, ["y"] = 0, ["z"] = 7, ["name"] = "mex_moreblocks:basalt_brick"}, {["x"] = 7, ["y"] = 1, ["z"] = 1, ["name"] = "mex_moreblocks:basalt_brick"}, {["x"] = 7, ["y"] = 1, ["z"] = 2, ["name"] = "mex_moreblocks:basalt_brick"}, {["x"] = 7, ["y"] = 1, ["z"] = 4, ["name"] = "mex_moreblocks:basalt_brick"}, {["x"] = 7, ["y"] = 1, ["z"] = 5, ["name"] = "mex_moreblocks:basalt_brick"}, {["x"] = 7, ["y"] = 1, ["z"] = 6, ["name"] = "mex_moreblocks:basalt_brick"}, {["x"] = 7, ["y"] = 1, ["z"] = 7, ["name"] = "mex_moreblocks:basalt_brick"}, {["x"] = 7, ["y"] = 2, ["z"] = 1, ["name"] = "mex_moreblocks:basalt_brick"}, {["x"] = 7, ["y"] = 2, ["z"] = 2, ["name"] = "mex_moreblocks:basalt_brick"}, {["x"] = 7, ["y"] = 2, ["z"] = 4, ["name"] = "mex_moreblocks:basalt_brick"}, {["x"] = 7, ["y"] = 2, ["z"] = 5, ["name"] = "mex_moreblocks:basalt_brick"}, {["x"] = 7, ["y"] = 2, ["z"] = 6, ["name"] = "mex_moreblocks:basalt_brick"}, {["x"] = 7, ["y"] = 3, ["z"] = 1, ["name"] = "mex_moreblocks:basalt_brick"}, {["x"] = 7, ["y"] = 3, ["z"] = 2, ["name"] = "mex_moreblocks:basalt_brick"}, {["x"] = 7, ["y"] = 3, ["z"] = 3, ["name"] = "mex_moreblocks:basalt_brick"}, {["x"] = 7, ["y"] = 3, ["z"] = 4, ["name"] = "mex_moreblocks:basalt_brick"}, {["x"] = 7, ["y"] = 3, ["z"] = 5, ["name"] = "mex_moreblocks:basalt_brick"}, {["x"] = 7, ["y"] = 3, ["z"] = 6, ["name"] = "mex_moreblocks:basalt_brick"}, {["x"] = 7, ["y"] = 4, ["z"] = 1, ["name"] = "mex_moreblocks:basalt_brick"}, {["x"] = 7, ["y"] = 4, ["z"] = 2, ["name"] = "mex_moreblocks:basalt_brick"}, {["x"] = 7, ["y"] = 4, ["z"] = 3, ["name"] = "mex_moreblocks:basalt_brick"}, {["x"] = 7, ["y"] = 4, ["z"] = 4, ["name"] = "default:pine_wood"}, {["x"] = 7, ["y"] = 4, ["z"] = 5, ["name"] = "mex_moreblocks:basalt_brick"}, {["x"] = 7, ["y"] = 4, ["z"] = 6, ["name"] = "mex_moreblocks:basalt_brick"}, {["x"] = 7, ["y"] = 5, ["z"] = 1, ["name"] = "mex_moreblocks:basalt_brick"}, {["x"] = 7, ["y"] = 5, ["z"] = 2, ["name"] = "mex_moreblocks:basalt_brick"}, {["x"] = 7, ["y"] = 5, ["z"] = 3, ["name"] = "mex_moreblocks:basalt_brick"}, {["x"] = 7, ["y"] = 5, ["z"] = 4, ["name"] = "mex_moreblocks:basalt_brick"}, {["x"] = 7, ["y"] = 5, ["z"] = 5, ["name"] = "mex_moreblocks:basalt_brick"}, {["x"] = 7, ["y"] = 5, ["z"] = 6, ["name"] = "mex_moreblocks:basalt_brick"}, {["x"] = 7, ["y"] = 6, ["z"] = 1, ["name"] = "mex_moreblocks:basalt_brick"}, {["x"] = 7, ["y"] = 6, ["z"] = 2, ["name"] = "mex_moreblocks:basalt_brick"}, {["x"] = 7, ["y"] = 6, ["z"] = 3, ["name"] = "mex_moreblocks:basalt_brick"}, {["x"] = 7, ["y"] = 6, ["z"] = 4, ["name"] = "mex_moreblocks:basalt_brick"}, {["x"] = 7, ["y"] = 6, ["z"] = 5, ["name"] = "mex_moreblocks:basalt_brick"}, {["x"] = 7, ["param2"] = 2, ["y"] = 6, ["param1"] = 14, ["z"] = 6, ["name"] = "stairs:stair_basalt_brick"}, {["x"] = 7, ["y"] = 7, ["z"] = 1, ["name"] = "mex_moreblocks:basalt_brick"}, {["x"] = 7, ["y"] = 7, ["z"] = 2, ["name"] = "mex_moreblocks:basalt_brick"}, {["x"] = 7, ["y"] = 7, ["z"] = 3, ["name"] = "mex_moreblocks:basalt_brick"}, {["x"] = 7, ["y"] = 7, ["z"] = 4, ["name"] = "mex_moreblocks:basalt_brick"}, {["x"] = 7, ["y"] = 7, ["z"] = 5, ["name"] = "mex_moreblocks:basalt_brick"}, {["x"] = 7, ["y"] = 8, ["z"] = 2, ["name"] = "mex_moreblocks:basalt_brick"}, {["x"] = 7, ["y"] = 8, ["z"] = 3, ["name"] = "mex_moreblocks:basalt_brick"}, {["x"] = 7, ["y"] = 8, ["z"] = 4, ["name"] = "mex_moreblocks:basalt_brick"}, {["x"] = 7, ["y"] = 8, ["z"] = 5, ["name"] = "mex_moreblocks:basalt_brick"}, {["x"] = 7, ["param2"] = 1, ["y"] = 9, ["param1"] = 14, ["z"] = 2, ["name"] = "stairs:stair_basalt_brick"}, {["x"] = 7, ["param2"] = 1, ["y"] = 9, ["param1"] = 13, ["z"] = 3, ["name"] = "stairs:stair_basalt_brick"}, {["x"] = 7, ["param2"] = 1, ["y"] = 9, ["param1"] = 13, ["z"] = 4, ["name"] = "stairs:stair_basalt_brick"}, {["x"] = 7, ["param2"] = 2, ["y"] = 9, ["param1"] = 14, ["z"] = 5, ["name"] = "stairs:stair_outer_basalt_brick"}, {["x"] = 8, ["param2"] = 4, ["y"] = 0, ["param1"] = 14, ["z"] = 0, ["name"] = "mex_moreblocks:vine"}, {["x"] = 8, ["y"] = 0, ["z"] = 1, ["name"] = "mex_moreblocks:basalt_brick"}, {["x"] = 8, ["y"] = 0, ["z"] = 2, ["name"] = "mex_moreblocks:marble_tile"}, {["x"] = 8, ["y"] = 0, ["z"] = 3, ["name"] = "mex_moreblocks:marble_tile"}, {["x"] = 8, ["y"] = 0, ["z"] = 4, ["name"] = "mex_moreblocks:marble_tile"}, {["x"] = 8, ["y"] = 0, ["z"] = 5, ["name"] = "mex_moreblocks:basalt_brick"}, {["x"] = 8, ["param2"] = 4, ["y"] = 1, ["param1"] = 14, ["z"] = 0, ["name"] = "mex_moreblocks:vine"}, {["x"] = 8, ["y"] = 1, ["z"] = 1, ["name"] = "mex_moreblocks:basalt_brick"}, {["x"] = 8, ["y"] = 1, ["z"] = 5, ["name"] = "mex_moreblocks:basalt_brick"}, {["x"] = 8, ["y"] = 2, ["z"] = 1, ["name"] = "mex_moreblocks:basalt_brick"}, {["x"] = 8, ["y"] = 2, ["z"] = 5, ["name"] = "mex_moreblocks:basalt_brick"}, {["x"] = 8, ["y"] = 3, ["z"] = 1, ["name"] = "mex_moreblocks:basalt_brick"}, {["x"] = 8, ["y"] = 3, ["z"] = 5, ["name"] = "mex_moreblocks:basalt_brick"}, {["x"] = 8, ["y"] = 4, ["z"] = 1, ["name"] = "mex_moreblocks:basalt_brick"}, {["x"] = 8, ["y"] = 4, ["z"] = 2, ["name"] = "default:pine_wood"}, {["x"] = 8, ["y"] = 4, ["z"] = 3, ["name"] = "default:pine_wood"}, {["x"] = 8, ["y"] = 4, ["z"] = 4, ["name"] = "default:pine_wood"}, {["x"] = 8, ["y"] = 4, ["z"] = 5, ["name"] = "mex_moreblocks:basalt_brick"}, {["x"] = 8, ["y"] = 5, ["z"] = 1, ["name"] = "mex_moreblocks:basalt_brick"}, {["x"] = 8, ["y"] = 5, ["z"] = 5, ["name"] = "mex_moreblocks:basalt_brick"}, {["x"] = 8, ["y"] = 6, ["z"] = 1, ["name"] = "mex_moreblocks:basalt_brick"}, {["x"] = 8, ["y"] = 6, ["z"] = 5, ["name"] = "mex_moreblocks:basalt_brick"}, {["x"] = 8, ["y"] = 7, ["z"] = 1, ["name"] = "mex_moreblocks:basalt_brick"}, {["x"] = 8, ["y"] = 7, ["z"] = 5, ["name"] = "mex_moreblocks:basalt_brick"}, {["x"] = 8, ["y"] = 8, ["z"] = 1, ["name"] = "mex_moreblocks:basalt_brick"}, {["x"] = 8, ["y"] = 8, ["z"] = 2, ["name"] = "mex_moreblocks:basalt_brick"}, {["x"] = 8, ["y"] = 8, ["z"] = 3, ["name"] = "mex_moreblocks:basalt_brick"}, {["x"] = 8, ["y"] = 8, ["z"] = 4, ["name"] = "mex_moreblocks:basalt_brick"}, {["x"] = 8, ["y"] = 8, ["z"] = 5, ["name"] = "mex_moreblocks:basalt_brick"}, {["x"] = 8, ["y"] = 9, ["param1"] = 14, ["z"] = 1, ["name"] = "stairs:stair_basalt_brick"}, {["x"] = 8, ["y"] = 9, ["z"] = 2, ["name"] = "mex_moreblocks:basalt_brick"}, {["x"] = 8, ["y"] = 9, ["z"] = 3, ["name"] = "mex_moreblocks:basalt_brick"}, {["x"] = 8, ["y"] = 9, ["z"] = 4, ["name"] = "mex_moreblocks:basalt_brick"}, {["x"] = 8, ["param2"] = 2, ["y"] = 9, ["param1"] = 14, ["z"] = 5, ["name"] = "stairs:stair_basalt_brick"}, {["x"] = 8, ["param2"] = 1, ["y"] = 10, ["param1"] = 14, ["z"] = 2, ["name"] = "stairs:stair_outer_basalt_brick"}, {["x"] = 8, ["param2"] = 1, ["y"] = 10, ["param1"] = 13, ["z"] = 3, ["name"] = "stairs:stair_basalt_brick"}, {["x"] = 8, ["param2"] = 2, ["y"] = 10, ["param1"] = 14, ["z"] = 4, ["name"] = "stairs:stair_outer_basalt_brick"}, {["x"] = 9, ["param2"] = 4, ["y"] = 0, ["param1"] = 14, ["z"] = 0, ["name"] = "mex_moreblocks:vine"}, {["x"] = 9, ["y"] = 0, ["z"] = 1, ["name"] = "mex_moreblocks:basalt_brick"}, {["x"] = 9, ["y"] = 0, ["z"] = 2, ["name"] = "mex_moreblocks:marble_tile"}, {["x"] = 9, ["y"] = 0, ["z"] = 3, ["name"] = "mex_moreblocks:marble_tile"}, {["x"] = 9, ["y"] = 0, ["z"] = 4, ["name"] = "mex_moreblocks:marble_tile"}, {["x"] = 9, ["y"] = 0, ["z"] = 5, ["name"] = "mex_moreblocks:basalt_brick"}, {["x"] = 9, ["param2"] = 4, ["y"] = 1, ["param1"] = 14, ["z"] = 0, ["name"] = "mex_moreblocks:vine"}, {["x"] = 9, ["y"] = 1, ["z"] = 1, ["name"] = "mex_moreblocks:basalt_brick"}, {["x"] = 9, ["param2"] = 4, ["y"] = 1, ["param1"] = 10, ["z"] = 4, ["name"] = "default:ladder_wood"}, {["x"] = 9, ["y"] = 1, ["z"] = 5, ["name"] = "mex_moreblocks:basalt_brick"}, {["x"] = 9, ["param2"] = 2, ["y"] = 2, ["param1"] = 14, ["z"] = 1, ["name"] = "xpanes:obsidian_pane_flat"}, {["x"] = 9, ["param2"] = 4, ["y"] = 2, ["param1"] = 27, ["z"] = 4, ["name"] = "default:ladder_wood"}, {["x"] = 9, ["y"] = 2, ["z"] = 5, ["name"] = "mex_moreblocks:basalt_brick"}, {["x"] = 9, ["param2"] = 2, ["y"] = 3, ["param1"] = 14, ["z"] = 1, ["name"] = "xpanes:obsidian_pane_flat"}, {["x"] = 9, ["param2"] = 4, ["y"] = 3, ["param1"] = 11, ["z"] = 4, ["name"] = "default:ladder_wood"}, {["x"] = 9, ["y"] = 3, ["z"] = 5, ["name"] = "mex_moreblocks:basalt_brick"}, {["x"] = 9, ["y"] = 4, ["z"] = 1, ["name"] = "mex_moreblocks:basalt_brick"}, {["x"] = 9, ["y"] = 4, ["z"] = 2, ["name"] = "default:pine_wood"}, {["x"] = 9, ["y"] = 4, ["z"] = 3, ["name"] = "default:pine_wood"}, {["x"] = 9, ["param2"] = 4, ["y"] = 4, ["param1"] = 10, ["z"] = 4, ["name"] = "default:ladder_wood"}, {["x"] = 9, ["y"] = 4, ["z"] = 5, ["name"] = "mex_moreblocks:basalt_brick"}, {["x"] = 9, ["y"] = 5, ["z"] = 1, ["name"] = "mex_moreblocks:basalt_brick"}, {["x"] = 9, ["param2"] = 4, ["y"] = 5, ["param1"] = 10, ["z"] = 4, ["name"] = "default:ladder_wood"}, {["x"] = 9, ["y"] = 5, ["z"] = 5, ["name"] = "mex_moreblocks:basalt_brick"}, {["x"] = 9, ["y"] = 6, ["z"] = 5, ["name"] = "mex_moreblocks:basalt_brick"}, {["x"] = 9, ["param2"] = 2, ["y"] = 7, ["param1"] = 14, ["z"] = 1, ["name"] = "xpanes:obsidian_pane_flat"}, {["x"] = 9, ["y"] = 7, ["z"] = 5, ["name"] = "mex_moreblocks:basalt_brick"}, {["x"] = 9, ["y"] = 8, ["z"] = 1, ["name"] = "mex_moreblocks:basalt_brick"}, {["x"] = 9, ["y"] = 8, ["z"] = 2, ["name"] = "mex_moreblocks:basalt_brick"}, {["x"] = 9, ["y"] = 8, ["z"] = 3, ["name"] = "mex_moreblocks:basalt_brick"}, {["x"] = 9, ["y"] = 8, ["z"] = 4, ["name"] = "mex_moreblocks:basalt_brick"}, {["x"] = 9, ["y"] = 8, ["z"] = 5, ["name"] = "mex_moreblocks:basalt_brick"}, {["x"] = 9, ["y"] = 9, ["param1"] = 14, ["z"] = 1, ["name"] = "stairs:stair_basalt_brick"}, {["x"] = 9, ["y"] = 9, ["z"] = 2, ["name"] = "mex_moreblocks:basalt_brick"}, {["x"] = 9, ["y"] = 9, ["z"] = 3, ["name"] = "mex_moreblocks:basalt_brick"}, {["x"] = 9, ["y"] = 9, ["z"] = 4, ["name"] = "mex_moreblocks:basalt_brick"}, {["x"] = 9, ["param2"] = 2, ["y"] = 9, ["param1"] = 14, ["z"] = 5, ["name"] = "stairs:stair_basalt_brick"}, {["x"] = 9, ["y"] = 10, ["param1"] = 14, ["z"] = 2, ["name"] = "stairs:stair_basalt_brick"}, {["x"] = 9, ["y"] = 10, ["z"] = 3, ["name"] = "mex_moreblocks:basalt_brick"}, {["x"] = 9, ["param2"] = 2, ["y"] = 10, ["param1"] = 14, ["z"] = 4, ["name"] = "stairs:stair_basalt_brick"}, {["x"] = 9, ["y"] = 11, ["param1"] = 14, ["z"] = 3, ["name"] = "stairs:slab_basalt_brick"}, {["x"] = 10, ["y"] = 0, ["z"] = 1, ["name"] = "mex_moreblocks:basalt_brick"}, {["x"] = 10, ["y"] = 0, ["z"] = 2, ["name"] = "mex_moreblocks:marble_tile"}, {["x"] = 10, ["y"] = 0, ["z"] = 3, ["name"] = "mex_moreblocks:marble_tile"}, {["x"] = 10, ["y"] = 0, ["z"] = 4, ["name"] = "mex_moreblocks:marble_tile"}, {["x"] = 10, ["y"] = 0, ["z"] = 5, ["name"] = "mex_moreblocks:basalt_brick"}, {["x"] = 10, ["y"] = 1, ["z"] = 1, ["name"] = "mex_moreblocks:basalt_brick"}, {["x"] = 10, ["y"] = 1, ["z"] = 5, ["name"] = "mex_moreblocks:basalt_brick"}, {["x"] = 10, ["y"] = 2, ["z"] = 1, ["name"] = "mex_moreblocks:basalt_brick"}, {["x"] = 10, ["y"] = 2, ["z"] = 5, ["name"] = "mex_moreblocks:basalt_brick"}, {["x"] = 10, ["y"] = 3, ["z"] = 1, ["name"] = "mex_moreblocks:basalt_brick"}, {["x"] = 10, ["y"] = 3, ["z"] = 5, ["name"] = "mex_moreblocks:basalt_brick"}, {["x"] = 10, ["y"] = 4, ["z"] = 1, ["name"] = "mex_moreblocks:basalt_brick"}, {["x"] = 10, ["y"] = 4, ["z"] = 2, ["name"] = "default:pine_wood"}, {["x"] = 10, ["y"] = 4, ["z"] = 3, ["name"] = "default:pine_wood"}, {["x"] = 10, ["y"] = 4, ["z"] = 4, ["name"] = "default:pine_wood"}, {["x"] = 10, ["y"] = 4, ["z"] = 5, ["name"] = "mex_moreblocks:basalt_brick"}, {["x"] = 10, ["y"] = 5, ["z"] = 1, ["name"] = "mex_moreblocks:basalt_brick"}, {["x"] = 10, ["y"] = 5, ["z"] = 5, ["name"] = "mex_moreblocks:basalt_brick"}, {["x"] = 10, ["y"] = 6, ["z"] = 1, ["name"] = "mex_moreblocks:basalt_brick"}, {["x"] = 10, ["y"] = 6, ["z"] = 5, ["name"] = "mex_moreblocks:basalt_brick"}, {["x"] = 10, ["y"] = 7, ["z"] = 1, ["name"] = "mex_moreblocks:basalt_brick"}, {["x"] = 10, ["y"] = 7, ["z"] = 5, ["name"] = "mex_moreblocks:basalt_brick"}, {["x"] = 10, ["y"] = 8, ["z"] = 1, ["name"] = "mex_moreblocks:basalt_brick"}, {["x"] = 10, ["y"] = 8, ["z"] = 2, ["name"] = "mex_moreblocks:basalt_brick"}, {["x"] = 10, ["y"] = 8, ["z"] = 3, ["name"] = "mex_moreblocks:basalt_brick"}, {["x"] = 10, ["y"] = 8, ["z"] = 4, ["name"] = "mex_moreblocks:basalt_brick"}, {["x"] = 10, ["y"] = 8, ["z"] = 5, ["name"] = "mex_moreblocks:basalt_brick"}, {["x"] = 10, ["y"] = 9, ["param1"] = 14, ["z"] = 1, ["name"] = "stairs:stair_basalt_brick"}, {["x"] = 10, ["y"] = 9, ["z"] = 2, ["name"] = "mex_moreblocks:basalt_brick"}, {["x"] = 10, ["y"] = 9, ["z"] = 3, ["name"] = "mex_moreblocks:basalt_brick"}, {["x"] = 10, ["y"] = 9, ["z"] = 4, ["name"] = "mex_moreblocks:basalt_brick"}, {["x"] = 10, ["param2"] = 2, ["y"] = 9, ["param1"] = 14, ["z"] = 5, ["name"] = "stairs:stair_basalt_brick"}, {["x"] = 10, ["y"] = 10, ["param1"] = 14, ["z"] = 2, ["name"] = "stairs:stair_outer_basalt_brick"}, {["x"] = 10, ["param2"] = 3, ["y"] = 10, ["param1"] = 13, ["z"] = 3, ["name"] = "stairs:stair_basalt_brick"}, {["x"] = 10, ["param2"] = 3, ["y"] = 10, ["param1"] = 14, ["z"] = 4, ["name"] = "stairs:stair_outer_basalt_brick"}, {["x"] = 11, ["y"] = 0, ["z"] = 1, ["name"] = "mex_moreblocks:basalt_brick"}, {["x"] = 11, ["y"] = 0, ["z"] = 2, ["name"] = "mex_moreblocks:basalt_brick"}, {["x"] = 11, ["y"] = 0, ["z"] = 3, ["name"] = "mex_moreblocks:basalt_brick"}, {["x"] = 11, ["y"] = 0, ["z"] = 4, ["name"] = "mex_moreblocks:basalt_brick"}, {["x"] = 11, ["y"] = 0, ["z"] = 5, ["name"] = "mex_moreblocks:basalt_brick"}, {["x"] = 11, ["y"] = 1, ["z"] = 2, ["name"] = "mex_moreblocks:basalt_brick"}, {["x"] = 11, ["y"] = 1, ["z"] = 3, ["name"] = "mex_moreblocks:basalt_brick"}, {["x"] = 11, ["y"] = 1, ["z"] = 4, ["name"] = "mex_moreblocks:basalt_brick"}, {["x"] = 11, ["y"] = 1, ["z"] = 5, ["name"] = "mex_moreblocks:basalt_brick"}, {["x"] = 11, ["y"] = 2, ["z"] = 1, ["name"] = "mex_moreblocks:basalt_brick"}, {["x"] = 11, ["y"] = 2, ["z"] = 2, ["name"] = "mex_moreblocks:basalt_brick"}, {["x"] = 11, ["param2"] = 1, ["y"] = 2, ["param1"] = 12, ["z"] = 3, ["name"] = "xpanes:obsidian_pane_flat"}, {["x"] = 11, ["y"] = 2, ["z"] = 4, ["name"] = "mex_moreblocks:basalt_brick"}, {["x"] = 11, ["y"] = 2, ["z"] = 5, ["name"] = "mex_moreblocks:basalt_brick"}, {["x"] = 11, ["y"] = 3, ["z"] = 1, ["name"] = "mex_moreblocks:basalt_brick"}, {["x"] = 11, ["y"] = 3, ["z"] = 2, ["name"] = "mex_moreblocks:basalt_brick"}, {["x"] = 11, ["y"] = 3, ["z"] = 4, ["name"] = "mex_moreblocks:basalt_brick"}, {["x"] = 11, ["y"] = 3, ["z"] = 5, ["name"] = "mex_moreblocks:basalt_brick"}, {["x"] = 11, ["y"] = 4, ["z"] = 1, ["name"] = "mex_moreblocks:basalt_brick"}, {["x"] = 11, ["y"] = 4, ["z"] = 2, ["name"] = "mex_moreblocks:basalt_brick"}, {["x"] = 11, ["y"] = 4, ["z"] = 3, ["name"] = "mex_moreblocks:basalt_brick"}, {["x"] = 11, ["y"] = 4, ["z"] = 4, ["name"] = "mex_moreblocks:basalt_brick"}, {["x"] = 11, ["y"] = 5, ["z"] = 2, ["name"] = "mex_moreblocks:basalt_brick"}, {["x"] = 11, ["y"] = 5, ["z"] = 3, ["name"] = "mex_moreblocks:basalt_brick"}, {["x"] = 11, ["y"] = 5, ["z"] = 4, ["name"] = "mex_moreblocks:basalt_brick"}, {["x"] = 11, ["y"] = 5, ["z"] = 5, ["name"] = "mex_moreblocks:basalt_brick"}, {["x"] = 11, ["y"] = 6, ["z"] = 1, ["name"] = "mex_moreblocks:basalt_brick"}, {["x"] = 11, ["y"] = 6, ["z"] = 2, ["name"] = "mex_moreblocks:basalt_brick"}, {["x"] = 11, ["param2"] = 1, ["y"] = 6, ["param1"] = 13, ["z"] = 3, ["name"] = "xpanes:obsidian_pane_flat"}, {["x"] = 11, ["y"] = 6, ["z"] = 4, ["name"] = "mex_moreblocks:basalt_brick"}, {["x"] = 11, ["y"] = 6, ["z"] = 5, ["name"] = "mex_moreblocks:basalt_brick"}, {["x"] = 11, ["y"] = 7, ["z"] = 1, ["name"] = "mex_moreblocks:basalt_brick"}, {["x"] = 11, ["y"] = 7, ["z"] = 2, ["name"] = "mex_moreblocks:basalt_brick"}, {["x"] = 11, ["param2"] = 1, ["y"] = 7, ["param1"] = 13, ["z"] = 3, ["name"] = "xpanes:obsidian_pane_flat"}, {["x"] = 11, ["y"] = 7, ["z"] = 4, ["name"] = "mex_moreblocks:basalt_brick"}, {["x"] = 11, ["y"] = 8, ["z"] = 2, ["name"] = "mex_moreblocks:basalt_brick"}, {["x"] = 11, ["y"] = 8, ["z"] = 3, ["name"] = "mex_moreblocks:basalt_brick"}, {["x"] = 11, ["y"] = 8, ["z"] = 4, ["name"] = "mex_moreblocks:basalt_brick"}, {["x"] = 11, ["param2"] = 3, ["y"] = 9, ["param1"] = 14, ["z"] = 2, ["name"] = "stairs:stair_basalt_brick"}, {["x"] = 11, ["param2"] = 3, ["y"] = 9, ["param1"] = 13, ["z"] = 3, ["name"] = "stairs:stair_basalt_brick"}, {["x"] = 11, ["param2"] = 3, ["y"] = 9, ["param1"] = 14, ["z"] = 4, ["name"] = "stairs:stair_basalt_brick"}, {["x"] = 12, ["param2"] = 3, ["y"] = 0, ["param1"] = 14, ["z"] = 1, ["name"] = "mex_moreblocks:vine"}, {["x"] = 12, ["param2"] = 3, ["y"] = 0, ["param1"] = 14, ["z"] = 2, ["name"] = "mex_moreblocks:vine"}, {["x"] = 12, ["param2"] = 3, ["y"] = 0, ["param1"] = 13, ["z"] = 3, ["name"] = "mex_moreblocks:vine"}, {["x"] = 12, ["param2"] = 3, ["y"] = 1, ["param1"] = 14, ["z"] = 2, ["name"] = "mex_moreblocks:vine"}, {["x"] = 12, ["param2"] = 3, ["y"] = 2, ["param1"] = 14, ["z"] = 1, ["name"] = "mex_moreblocks:vine"}, {["x"] = 12, ["param2"] = 3, ["y"] = 2, ["param1"] = 14, ["z"] = 2, ["name"] = "mex_moreblocks:vine"}, {["x"] = 12, ["param2"] = 3, ["y"] = 2, ["param1"] = 14, ["z"] = 5, ["name"] = "mex_moreblocks:vine"}, {["x"] = 12, ["param2"] = 3, ["y"] = 3, ["param1"] = 14, ["z"] = 2, ["name"] = "mex_moreblocks:vine"}, {["x"] = 12, ["param2"] = 3, ["y"] = 3, ["param1"] = 14, ["z"] = 5, ["name"] = "mex_moreblocks:vine"}, {["x"] = 12, ["param2"] = 3, ["y"] = 4, ["param1"] = 14, ["z"] = 2, ["name"] = "mex_moreblocks:vine"}, {["x"] = 12, ["param2"] = 3, ["y"] = 4, ["param1"] = 13, ["z"] = 3, ["name"] = "mex_moreblocks:vine"}, {["x"] = 12, ["param2"] = 3, ["y"] = 5, ["param1"] = 14, ["z"] = 3, ["name"] = "mex_moreblocks:vine"}, {["x"] = 12, ["param2"] = 3, ["y"] = 5, ["param1"] = 14, ["z"] = 4, ["name"] = "mex_moreblocks:vine"}}